Workbook
Name Celdap39: 'OPI Constr'!$O$39
Name Celda39: 'OPI Rentas'!$A$38:$C$39
Name objetivi: 'OPI Constr'!$F$308
Name Celdap39: 'OPI Rentas'!$O$39
Name objetivi: 'OPI Rentas'!$F$381
Name Celda39: 'OPI Constr'!$A$38:$C$39

Sheet Fotos
A1: Nombre Imagen | B1: Link | C1: id | D1: URL | E1: Foto
A2: 2.jpg | B2: https://drive.google.com/uc?export=download&id= | C2: 1uCi2KXuJ7zjI3RAMnn9V5LcBtN9V-fhU | D2: {=IF(A2:A996="",,B2:B996&C2:C996)} -> https://drive.google.com/uc?export=download&id=1uCi2KXuJ7zjI3RAMnn9V5LcBtN9V-fhU | E2: {=IF(A2:A996="",,IMAGE(B2:B996&C2:C996,2))}
A3: 3.jpg | B3: https://drive.google.com/uc?export=download&id= | C3: 10Xv2lp7_p27VDrtWaA6ZguMhaq65APMW | D3: https://drive.google.com/uc?export=download&id=10Xv2lp7_p27VDrtWaA6ZguMhaq65APMW
A4: 18.jpeg | B4: https://drive.google.com/uc?export=download&id= | C4: 18Ncfra8WvnT1pAQVfZL0qdWOaxqr3NEN | D4: https://drive.google.com/uc?export=download&id=18Ncfra8WvnT1pAQVfZL0qdWOaxqr3NEN
A5: 17.jpeg | B5: https://drive.google.com/uc?export=download&id= | C5: 1yQIm9vwB0ttAv5TzuPLErZ2lxJ0EmEsM | D5: https://drive.google.com/uc?export=download&id=1yQIm9vwB0ttAv5TzuPLErZ2lxJ0EmEsM
A6: 15.jpeg | B6: https://drive.google.com/uc?export=download&id= | C6: 1g3-ALO6-_lRCAA68D2pb0vcRQkIiu3x6 | D6: https://drive.google.com/uc?export=download&id=1g3-ALO6-_lRCAA68D2pb0vcRQkIiu3x6
A7: 16.jpeg | B7: https://drive.google.com/uc?export=download&id= | C7: 135Fkj9z2TAiLqjt-NHW8slfpiGZoRHWw | D7: https://drive.google.com/uc?export=download&id=135Fkj9z2TAiLqjt-NHW8slfpiGZoRHWw
A8: 14.jpeg | B8: https://drive.google.com/uc?export=download&id= | C8: 1LSXqfxmYaSy4W8tmyN2ZIYpDY4HVW3Bc | D8: https://drive.google.com/uc?export=download&id=1LSXqfxmYaSy4W8tmyN2ZIYpDY4HVW3Bc
A9: 13.jpeg | B9: https://drive.google.com/uc?export=download&id= | C9: 1ootI2reS3zOEWwIDIPj52NqKyaiTqx-q | D9: https://drive.google.com/uc?export=download&id=1ootI2reS3zOEWwIDIPj52NqKyaiTqx-q
A10: 12.jpeg | B10: https://drive.google.com/uc?export=download&id= | C10: 1CxxSnrpMvDrmMtRuHFHboBjLdqGTGWD0 | D10: https://drive.google.com/uc?export=download&id=1CxxSnrpMvDrmMtRuHFHboBjLdqGTGWD0
A11: 11.jpeg | B11: https://drive.google.com/uc?export=download&id= | C11: 1Jry7NLsYl5OzJ_2uhRhdpLNckGrBjjeq | D11: https://drive.google.com/uc?export=download&id=1Jry7NLsYl5OzJ_2uhRhdpLNckGrBjjeq
A12: 10.jpeg | B12: https://drive.google.com/uc?export=download&id= | C12: 1VBqnJWPA6cKSsxaS8TywQ-nRxJrWW4RO | D12: https://drive.google.com/uc?export=download&id=1VBqnJWPA6cKSsxaS8TywQ-nRxJrWW4RO
A13: 9.jpeg | B13: https://drive.google.com/uc?export=download&id= | C13: 1706_ks01TI4s7uCDGnSTFNha80pyfeHo | D13: https://drive.google.com/uc?export=download&id=1706_ks01TI4s7uCDGnSTFNha80pyfeHo
A14: 8.jpeg | B14: https://drive.google.com/uc?export=download&id= | C14: 1HDGcYiNVXfchE1ro_AZYfBomR95IOoWA | D14: https://drive.google.com/uc?export=download&id=1HDGcYiNVXfchE1ro_AZYfBomR95IOoWA
... A22: Fototeca - 12 de 21.jpeg | B22: https://drive.google.com/uc?export=download&id= | C22: 13nd0w41CZpT4qpTbInVaF-5ydZmdQrQM | D22: https://drive.google.com/uc?export=download&id=13nd0w41CZpT4qpTbInVaF-5ydZmdQrQM

Sheet Base Datos Avaluo
A1: Folio | B1: Fecha | C1: Visito | D1: Capturo | E1: Reviso | F1: Tipo Propiedad | G1: Municipio | H1: Colonia | I1: Dirección | J1: Latitud | K1: Longitud | L1: Ubicación GPS | M1: Vida Util Ponderada | N1: Edad ponderada | O1: M2 Terreno | P1: M2 Construccion | Q1: M2 Accesoria | R1: PU Terreno | S1: PU construcc | T1: Valor Terreno | U1: Valor Constr | V1: Valor Instalaciones | W1: Valor Fisico | X1: Valor de Mercado venta | Y1: % dif Fisico/Mercado | Z1: Valor mercado Renta | AA1: Renta factorada
A2: =Query_Formato!B4 -> 450814fd | B2: ='OPI Constr'!AG6 -> 46202 | C2: =Query_Formato!B6 -> 2c214683 | F2: ='OPI Constr'!E8 -> Casa Habitación | G2: ='OPI Constr'!AB72 -> Guadalajara | H2: ='OPI Constr'!AG74 -> San Elías | I2: ='OPI Constr'!E10 -> Pascal 2164, San Elías, 44246 Guadalajara, Jal. | L2: =Query_Formato!B10 | M2: ='OPI Constr'!I86 -> 49 | N2: ='OPI Constr'!A86 -> 21 | O2: ='OPI Constr'!C111 -> 91.97 | P2: ='OPI Constr'!K123 -> 74.2 | Q2: ='OPI Constr'!K135 -> 0 | R2: ='OPI Constr'!AC111 -> 10500 | S2: ='OPI Constr'!AL209 -> 32793.328 | T2: ='OPI Constr'!AJ111 -> 965685 | U2: ='OPI Constr'!AJ123+'OPI Constr'!AJ135 -> 835989.01 | V2: ='OPI Constr'!AJ157 -> 8472.6096 | W2: ='OPI Constr'!AJ159 -> 1810146.6 | X2: ='OPI Constr'!AJ161 -> 2433265 | Y2: ='OPI Constr'!AP161 -> 0.25608323 | AA2: ='OPI Constr'!AI166 -> 9732

Sheet OPI Loc Com b
AF1: 3314189492 | AI1: 3336320507
AF2: avaluos@avaluosyarquitectura.com.mx
AF3: avaluosyarquitectura2@gmail.com
O4: OPINIÓN DE VALOR | AF4: www.avaluosyarquitectura.com.mx
AF7: Fecha: | AH7: =TODAY() -> 46202
A9: OPINIÓN DE VALOR DE:
A11: UBICACIÓN:
A14: SOLICITANTE:
A16: PROPIETARIO:
F19: =VLOOKUP("1.jp*g",Fotos!$A$2:$E506,5,FALSE)
C23: =Query_Formato!B11 -> Intermedia
C25: =Query_Formato!B11 -> Intermedia
F45: =VLOOKUP("2.jp*g",Fotos!$A$2:$E506,5,FALSE)
AB74: El valor POR LOCAL corresponde comparando venta de locales | AD74: =+ROUND(AI164,-3) -> #DIV/0!
AB76: El valor POR LOCAL corresponde comparando renta de locales | AD76: =ROUND(AJ162,-3) -> #DIV/0!
A79: ANTECEDENTES
A81: SOLICITANTE: | K81: =O14
A83: UBICACIÓN: | K83: =O11
A85: CUENTA PREDIAL: | S85: CLAVE CATASTRAL:
A87: INMUEBLE: | K87: =O9
A88: PROPIETARIO: | K88: =O16
A90: OBJETO DEL ANÁLISIS: | X90: RÉGIMEN DE PROP:
A92: CARACTERÍSTICAS URBANAS Y DEL INMUEBLE
A94: SERVICIOS: | K94: =+CONCATENATE(AS105," ",AT105,", ",AS106," ",AT106,", ",AS107," ",AT107,", ",AS108," ",AT108,", ",AS109," ",AT109,", ",AS110," ",AT110,", ",AS111," ",AT111,", ",AS112," ",AT112,", ",AS113," ",AT113,".", ) -> SERVICIOS BÁSICOS: , AGUA POTABLE: , DRENAJE: , ENERGÍA ELÉCTRICA: , GAS: , ALUMBRADO EXTERIOR: , LÍNEAS TELEFÓNICAS: , VIALIDADES: , TRANSPORTE: .
A97: CLASIFICACIÓN DE LA ZONA: | AR97: AÑO ACTUAL | AS97: 2023
V99: C.O.S. | X99: C.U.S. | Z99: Fr Min | AC99: M2 Min. Lote | AF99: N° Est. | AH99: % Edif. Zona | AK99: Niveles | AN99: Niv. Ubicación | AR99: AÑO CONSTR.
A100: USO DEL SUELO: | F100: H1-U | K100: =UPPER(CONCATENATE(VLOOKUP(F100,'catalogo 2'!L15:N113,2,0)," ",(VLOOKUP(F100,'catalogo 2'!L15:N113,3,0)))) -> HABITACIONAL DENSIDAD MÍNIMA UNIFAMILIAR | V100: =VLOOKUP(F100,'catalogo 2'!L15:AE114,14,0) -> 0.4 | X100: =VLOOKUP(F100,'catalogo 2'!L15:AF114,16,0) -> 0.8 | Z100: =VLOOKUP(F100,'catalogo 2'!L15:AF114,11,0) -> 20 | AC100: =VLOOKUP(F100,'catalogo 2'!L15:AF114,10,0) -> 600 m2 | AF100: =VLOOKUP(F100,'catalogo 2'!L15:AF114,18,0) -> 4 | AH100: =+'OPI Constr'!AH100 | AN100: 0 - P.BAJA | AR100: EDAD | AS100: =AS97-AS99 -> 2023
A102: EDAD APROX. | F102: VIDA ÚTIL | I102: ED. REMANENTE | M102: EDAD TIPO | R102: CALIDAD | V102: CONSERVACIÓN | AA102: PROYECTO: | AH102: CLAVE | AL102: % EDIF. SUJETO
A103: =+AS100 -> 2023 | F103: =IF(OR(R103="MEDIO",R103="SUPERIOR",R103="LUJO"),70,60) -> 60 | I103: =IF(OR(R103="MEDIO",R103="SUPERIOR",R103="LUJO"),70,60)-A103 -> -1963 | M103: =VLOOKUP(A103,'catalogo 2'!C137:F142,4) -> #N/A | AG103: =+CONCATENATE(VLOOKUP(M103,'catalogo 2'!E144:F149,2,FALSE),".",VLOOKUP('OPI Loc Com b'!R103,'catalogo 2'!G144:H149,2,FALSE),".",VLOOKUP('OPI Loc Com b'!V103,'catalogo 2'!I144:J152,2,FALSE),".",VLOOKUP('OPI Loc Com b'!Z103,'catalogo 2'!L144:M153,2,FALSE)) -> #N/A
A105: MEDIDAS Y LINDEROS SEGÚN: | V105: =VLOOKUP("3.jp*g",Fotos!$A$2:$E506,5,FALSE) | AS105: SERVICIOS BÁSICOS:
AS106: AGUA POTABLE:
A107: Norte | AS107: DRENAJE:
A108: =IF($A$107="norte","Sur","Sureste") -> Sur | E108: =IF(E107<>"", E107, "") | AS108: ENERGÍA ELÉCTRICA:
A109: =IF($A$107="norte","Este","Noroeste") -> Este | AS109: GAS:
A110: =IF($A$107="norte","Oeste","Suroeste") -> Oeste | E110: =IF(E109<>"", E109, "") | AS110: ALUMBRADO EXTERIOR:
AS111: LÍNEAS TELEFÓNICAS:
A112: DESCRIPCIÓN DEL INMUEBLE | AS112: VIALIDADES:
A113: =+'OPI Constr'!$S$81 | AS113: TRANSPORTE:
A120: AVALÚO FÍSICO
C121: A) DEL TERRENO: | P121: LOTE TIPO: | Q121: VARIABLE
...

Sheet Query_Formato
A1: Atributo | B1: Valor | C1: Plantilla
A2: =IFERROR(__xludf.DUMMYFUNCTION("TRANSPOSE(QUERY(IMPORTRANGE(""1aF3RXZCNy_CKBDFezcCT7265looJ5_hSeKa4_qe8HZA"",""Visitas!A:EW""),""SELECT * WHERE Col3 ='450814fd'"",1))"),"ID") -> ID | B2: =IFERROR(__xludf.DUMMYFUNCTION("""COMPUTED_VALUE"""),"ba277a4d") -> ba277a4d | C2: ID
A3: =IFERROR(__xludf.DUMMYFUNCTION("""COMPUTED_VALUE"""),"Cliente") -> Cliente | B3: =IFERROR(__xludf.DUMMYFUNCTION("""COMPUTED_VALUE"""),"ba44bb30") -> ba44bb30 | C3: Cliente
A4: =IFERROR(__xludf.DUMMYFUNCTION("""COMPUTED_VALUE"""),"Avaluo") -> Avaluo | B4: =IFERROR(__xludf.DUMMYFUNCTION("""COMPUTED_VALUE"""),"450814fd") -> 450814fd | C4: Avaluo
A5: =IFERROR(__xludf.DUMMYFUNCTION("""COMPUTED_VALUE"""),"Fecha") -> Fecha | B5: =IFERROR(__xludf.DUMMYFUNCTION("""COMPUTED_VALUE"""),45975.0) -> 45975 | C5: Fecha
A6: =IFERROR(__xludf.DUMMYFUNCTION("""COMPUTED_VALUE"""),"Visitador") -> Visitador | B6: =IFERROR(__xludf.DUMMYFUNCTION("""COMPUTED_VALUE"""),"2c214683") -> 2c214683 | C6: Visitador
A7: =IFERROR(__xludf.DUMMYFUNCTION("""COMPUTED_VALUE"""),"Tipo de Avaluo") -> Tipo de Avaluo | B7: =IFERROR(__xludf.DUMMYFUNCTION("""COMPUTED_VALUE"""),"OPI") -> OPI | C7: Tipo de Avaluo
A8: =IFERROR(__xludf.DUMMYFUNCTION("""COMPUTED_VALUE"""),"SECCIÓN CARACTERÍSTICAS URBANAS") -> SECCIÓN CARACTERÍSTICAS URBANAS | C8: SECCIÓN CARACTERÍSTICAS URBANAS
A9: =IFERROR(__xludf.DUMMYFUNCTION("""COMPUTED_VALUE"""),"Direccion") -> Direccion | B9: =IFERROR(__xludf.DUMMYFUNCTION("""COMPUTED_VALUE"""),"Pascal 2164 Colonia San Elias Guadalajara Jalisco 44240") -> Pascal 2164 Colonia San Elias Guadalajara Jalisco 44240 | C9: Direccion
A10: =IFERROR(__xludf.DUMMYFUNCTION("""COMPUTED_VALUE"""),"Ubicacion GPS") -> Ubicacion GPS | C10: Ubicacion GPS
A11: =IFERROR(__xludf.DUMMYFUNCTION("""COMPUTED_VALUE"""),"Referencia Proximidad Urbana") -> Referencia Proximidad Urbana | B11: =IFERROR(__xludf.DUMMYFUNCTION("""COMPUTED_VALUE"""),"Intermedia") -> Intermedia | C11: Referencia Proximidad Urbana
A12: =IFERROR(__xludf.DUMMYFUNCTION("""COMPUTED_VALUE"""),"Nivel de Infraestructura") -> Nivel de Infraestructura | C12: Nivel de Infraestructura
A13: =IFERROR(__xludf.DUMMYFUNCTION("""COMPUTED_VALUE"""),"Agua Potable") -> Agua Potable | C13: Agua Potable
A14: =IFERROR(__xludf.DUMMYFUNCTION("""COMPUTED_VALUE"""),"Drenaje") -> Drenaje | B14: =IFERROR(__xludf.DUMMYFUNCTION("""COMPUTED_VALUE"""),"Entubado") -> Entubado | C14: Drenaje
A15: =IFERROR(__xludf.DUMMYFUNCTION("""COMPUTED_VALUE"""),"Electrificación") -> Electrificación | B15: =IFERROR(__xludf.DUMMYFUNCTION("""COMPUTED_VALUE"""),"Con Cableado Aereo") -> Con Cableado Aereo | C15: Electrificación
A16: =IFERROR(__xludf.DUMMYFUNCTION("""COMPUTED_VALUE"""),"Alumbrado Publico") -> Alumbrado Publico | B16: =IFERROR(__xludf.DUMMYFUNCTION("""COMPUTED_VALUE"""),"Con Cableado Aereo") -> Con Cableado Aereo | C16: Alumbrado Público
A17: =IFERROR(__xludf.DUMMYFUNCTION("""COMPUTED_VALUE"""),"Vialidades") -> Vialidades | B17: =IFERROR(__xludf.DUMMYFUNCTION("""COMPUTED_VALUE"""),"Asfalto") -> Asfalto | C17: Vialidades
A18: =IFERROR(__xludf.DUMMYFUNCTION("""COMPUTED_VALUE"""),"Señalización") -> Señalización | B18: =IFERROR(__xludf.DUMMYFUNCTION("""COMPUTED_VALUE"""),"Existe") -> Existe | C18: Señalización
A19: =IFERROR(__xludf.DUMMYFUNCTION("""COMPUTED_VALUE"""),"Transporte publico") -> Transporte publico | B19: =IFERROR(__xludf.DUMMYFUNCTION("""COMPUTED_VALUE"""),"Urbano") -> Urbano | C19: Transporte Público
A20: =IFERROR(__xludf.DUMMYFUNCTION("""COMPUTED_VALUE"""),"Clasificacion de la zona") -> Clasificacion de la zona | C20: Clasificacion de la zona
A21: =IFERROR(__xludf.DUMMYFUNCTION("""COMPUTED_VALUE"""),"Nivel de Equipamiento") -> Nivel de Equipamiento | C21: Nivel de Equipamiento
A22: =IFERROR(__xludf.DUMMYFUNCTION("""COMPUTED_VALUE"""),"Construcciones Predominantes") -> Construcciones Predominantes | B22: =IFERROR(__xludf.DUMMYFUNCTION("""COMPUTED_VALUE"""),"Casas Habitación") -> Casas Habitación | C22: Construcciones Predominantes
A23: =IFERROR(__xludf.DUMMYFUNCTION("""COMPUTED_VALUE"""),"Calidad de las Construcciones") -> Calidad de las Construcciones | C23: Calidad de las Construcciones
A24: =IFERROR(__xludf.DUMMYFUNCTION("""COMPUTED_VALUE"""),"Recoleccion de Basura") -> Recoleccion de Basura | B24: =IFERROR(__xludf.DUMMYFUNCTION("""COMPUTED_VALUE"""),"Municipal") -> Municipal | C24: Recoleccion de Basura
A25: =IFERROR(__xludf.DUMMYFUNCTION("""COMPUTED_VALUE"""),"Nivel socioeconómico") -> Nivel socioeconómico | B25: =IFERROR(__xludf.DUMMYFUNCTION("""COMPUTED_VALUE"""),"Medio-Medio") -> Medio-Medio | C25: Nivel socioeconómico
A26: =IFERROR(__xludf.DUMMYFUNCTION("""COMPUTED_VALUE"""),"Indice de Saturación en la zona") -> Indice de Saturación en la zona | C26: Indice de Saturación en la zona
A27: =IFERROR(__xludf.DUMMYFUNCTION("""COMPUTED_VALUE"""),"Densidaad de Población") -> Densidaad de Población | C27: Densidaad de Población
A28: =IFERROR(__xludf.DUMMYFUNCTION("""COMPUTED_VALUE"""),"Vias de Acceso") -> Vias de Acceso | C28: Vias de Acceso
A29: =IFERROR(__xludf.DUMMYFUNCTION("""COMPUTED_VALUE"""),"SECCIÓN GENERALES") -> SECCIÓN GENERALES | C29: SECCIÓN GENERALES
A30: =IFERROR(__xludf.DUMMYFUNCTION("""COMPUTED_VALUE"""),"Clave catastral") -> Clave catastral | C30: Clave catastral
A31: =IFERROR(__xludf.DUMMYFUNCTION("""COMPUTED_VALUE"""),"Num Predial") -> Num Predial | C31: Num Predial
A32: =IFERROR(__xludf.DUMMYFUNCTION("""COMPUTED_VALUE"""),"Tipo doc. referencia legal") -> Tipo doc. referencia legal | C32: Tipo doc. referencia legal
A33: =IFERROR(__xludf.DUMMYFUNCTION("""COMPUTED_VALUE"""),"Num Escritura") -> Num Escritura | C33: Num Escritura
A34: =IFERROR(__xludf.DUMMYFUNCTION("""COMPUTED_VALUE"""),"Notaria") -> Notaria | C34: Notaria
A35: =IFERROR(__xludf.DUMMYFUNCTION("""COMPUTED_VALUE"""),"Municipio") -> Municipio | C35: Municipio
A36: =IFERROR(__xludf.DUMMYFUNCTION("""COMPUTED_VALUE"""),"Regimen de Propiedad") -> Regimen de Propiedad | C36: Régimen de Propiedad
A37: =IFERROR(__xludf.DUMMYFUNCTION("""COMPUTED_VALUE"""),"Nombre Lic") -> Nombre Lic | C37: Nombre Lic
A38: =IFERROR(__xludf.DUMMYFUNCTION("""COMPUTED_VALUE"""),"Año de Construcción") -> Año de Construcción | C38: Año de Construcción
A39: =IFERROR(__xludf.DUMMYFUNCTION("""COMPUTED_VALUE"""),"Edad de las construcciones") -> Edad de las construcciones | C39: Edad de las construcciones
A40: =IFERROR(__xludf.DUMMYFUNCTION("""COMPUTED_VALUE"""),"Año Remodelación") -> Año Remodelación | B40: =IFERROR(__xludf.DUMMYFUNCTION("""COMPUTED_VALUE"""),2022.0) -> 2022 | C40: Año Remodelación
...

Sheet OPI Loc Com 
AF1: 3314189492 | AI1: 3336320507
O2: OPINIÓN DE VALOR | AF2: avaluos@avaluosyarquitectura.com.mx
AF3: avaluosyarquitectura2@gmail.com
AF4: www.avaluosyarquitectura.com.mx
A6: FOLIO | E6: =Query_Formato!B168 -> OPI-25-11-07-OF | AF6: Fecha: | AG6: =TODAY() -> 46202
A8: TIPO DE PROPIEDAD: | Z8: SOLICITANTE: | AA8: =Query_Formato!B156 -> Federico Arellano
A10: UBICACIÓN: | E10: =Query_Formato!B9 -> Pascal 2164 Colonia San Elias Guadalajara Jalisco 44240 | Z10: PROPIETARIO:
A12: =VLOOKUP("1.jp*g",Fotos!$A$2:$E399,5,FALSE) | W12: =VLOOKUP("2.jp*g",Fotos!$A$2:$E399,5,FALSE)
A33: RESUMEN
F34: VALORES DE VENTA SEGUN ANALISIS DE MERCADO DE VENTAS
A36: VALOR VENTA ESTIMADO PROMEDIO | N36: VALOR DE RENTA ESTIMADO PROMEDIO FACTORIZADO | AB36: REPRESENTATIVA DEL VALOR FÍSICO
A38: MÁXIMO sugerido | D38: =D40*1.1 -> #DIV/0! | N38: MÁXIMO | Q38: =Q40*1.1 -> #DIV/0! | AB38: TERRENO | AI38: =AP111 -> #DIV/0!
AB39: CONSTRUCCIONES | AI39: =AP123 -> #DIV/0!
A40: MEDIO o justo | D40: =ROUND(AJ200,-3) -> #DIV/0! | N40: MEDIO | Q40: =ROUND(AI149,-3) -> #DIV/0! | AB40: CONSTR. ACCESORIAS | AI40: =AP140 -> #DIV/0!
A42: MÍNIMO sugerido | D42: =D40*0.9 -> #DIV/0! | N42: MÍNIMO | Q42: =Q40*0.9 -> #DIV/0! | AB42: INSTALACIONES ACCESORIAS | AI42: =AN141
AI43: tot | AJ43: =SUM(AI38:AI43) -> #DIV/0!
A46: UNIDADES RENTABLES | K46: =AG87 | N46: TASA RENTA ANUAL SEGUN VALOR DE VENTA | W46: =AR149*10 -> 0.08 | AB46: CALIFICA CRÉDITO
A48: NIVELES | I48: =AK84 | N48: ESTADO DE CONSERVACIÓN | X48: =V87
A49: NIVEL UBICACIÓN | H49: =AN84 | N49: EDAD PONDERADA APROX | W49: =A87 -> 2026 | AB49: PLUSVALÍA ANUAL ESTIMADA
A50: TERRENO | H50: =C111 -> 0 | N50: EDAD REMANENTE | W50: =I87 -> -1966 | AB50: CERCANÍA
A51: CONSTRUCCIONES | H51: =K123 -> 0 | N51: AVANCE DE OBRA | W51: =AL87 -> 1 | AB51: DEMANDA DE LA ZONA
A52: DIFERENCIA ÷ VALOR DE VENTA Y CAPITALIZACIÓN DE RENTA | AB52: DIFERENCIA ÷ VALOR DE LAS CONSTRUCCIONES Y VALOR DE MERCADO DE LA PROPIEDAD
A54: =AJ144/AJ146/100 -> #DIV/0! | AB54: =$AR$144 -> #DIV/0!
A55: ESTO QUIERE DECIR QUE AL VENDER LA PROPIEDAD EXISTE UNA | AB55: ESTO QUIERE DECIR QUE AL VENDER LA PROPIEDAD EXISTE UNA
E59: VALORES DE RENTA SEGUN ANALISIS DE MERCADO DE RENTAS
A61: VALOR VENTA ESTIMADO ANALISIS DE MERCADO | N61: VALOR RENTA ESTIMADO ANALISIS DE MERCADO | AB61: TASA RENTA ANUAL SEGUN VALOR DE RENTA | AK61: =AR150*10 -> #DIV/0!
A63: MÁXIMO sugerido | D63: =D65*1.1 -> #DIV/0! | N63: MÁXIMO sugerido | Q63: =Q65*1.1 -> #DIV/0! | AB63: COSTO RENTA X M2 | AK63: =AL242 -> #DIV/0!
A65: MEDIO o justo | D65: =AJ146 -> #DIV/0! | N65: MEDIO o justo | Q65: =AI150 -> #DIV/0! | AB65: AL VENDER LA PROPIEDAD TIENE
A67: MÍNIMO sugerido | D67: =D65*0.9 -> #DIV/0! | N67: MÍNIMO sugerido | Q67: =Q65*0.9 -> #DIV/0!
A70: ANTECEDENTES
A72: CUENTA PREDIAL: | S72: CLAVE CATASTRAL:
A75: OBJETO DEL ANÁLISIS: | X75: RÉGIMEN DE PROP:
A78: SERVICIOS: | K78: =+CONCATENATE(AS89," ",AT89,", ",AS90," ",AT90,", ",AS91," ",AT91,", ",AS92," ",AT92,", ",AS93," ",AT93,", ",AS94," ",AT94,", ",AS95," ",AT95,", ",AS96," ",AT96,", ",AS97," ",AT97,".", ) -> SERVICIOS BÁSICOS: , AGUA POTABLE: , DRENAJE: , ENERGÍA ELÉCTRICA: , GAS: , ALUMBRADO EXTERIOR: , LÍNEAS TELEFÓNICAS: , VIALIDADES: , TRANSPORTE: .
A81: CLASIFICACIÓN DE LA ZONA: | AR81: AÑO ACTUAL | AS81: =YEAR(TODAY()) -> 2026
V83: C.O.S. | X83: C.U.S. | AA83: Fr Min | AC83: M2 Min. Lote | AF83: N° Est. | AH83: % Edif. Zona | AK83: Niveles | AN83: Niv. Ubicación | AR83: AÑO CONSTR.
A84: USO DEL SUELO: | K84: =UPPER(CONCATENATE(VLOOKUP(F84,'catalogo 2'!L15:N113,2,0)," ",(VLOOKUP(F84,'catalogo 2'!L15:N113,3,0)))) -> #N/A | V84: =VLOOKUP(F84,'catalogo 2'!M5:AJ85,14,0) -> #N/A | X84: =VLOOKUP(F84,'catalogo 2'!M5:AJ85,16,0) -> #N/A | AA84: =VLOOKUP(F84,'catalogo 2'!M5:AJ85,11,0) -> #N/A | AC84: =VLOOKUP(F84,'catalogo 2'!M5:AJ85,10,0) -> #N/A | AF84: =VLOOKUP(F84,'catalogo 2'!M5:AJ85,18,0) -> #N/A | AR84: EDAD | AS84: =AS81-AS83 -> 2026
A86: EDAD APROX. | F86: VIDA ÚTIL | I86: ED. REMANENTE | M86: EDAD TIPO | R86: CALIDAD | V86: CONSERVACIÓN | AA86: PROYECTO: | AG86: UNID. RENTABLES | AL86: % EDIF. SUJETO
A87: =+AS84 -> 2026 | F87: =IF(OR(R87="MEDIO",R87="SUPERIOR",R87="LUJO"),70,60) -> 60 | I87: =IF(OR(R87="MEDIO",R87="SUPERIOR",R87="LUJO"),70,60)-A87 -> -1966 | AL87: 1
A89: MEDIDAS Y LINDEROS SEGÚN: | I89: Medición del terreno | X89: =VLOOKUP("3.jp*g",Fotos!$A$2:$E399,5,FALSE) | AS89: SERVICIOS BÁSICOS:
AS90: AGUA POTABLE:
...

Sheet OPI Terreno
AF1: 3314189492 | AI1: 3336320507
O2: OPINIÓN DE VALOR | AF2: avaluos@avaluosyarquitectura.com.mx
AF3: avaluosyarquitectura2@gmail.com
AF4: www.avaluosyarquitectura.com.mx
A6: FOLIO | E6: =Query_Formato!B168 -> OPI-25-11-07-OF | AF6: Fecha: | AG6: =TODAY() -> 46202
A8: TIPO DE PROPIEDAD: | Y8: SOLICITANTE: | Z8: =Query_Formato!B156 -> Federico Arellano
A10: UBICACIÓN: | D10: =Query_Formato!B9 -> Pascal 2164 Colonia San Elias Guadalajara Jalisco 44240 | Y10: PROPIETARIO:
A12: =VLOOKUP("1.jp*g",Fotos!$A$2:$E395,5,FALSE) | V12: =VLOOKUP("2.jp*g",Fotos!$A$2:$E395,5,FALSE)
A33: RESUMEN
A35: VALOR VENTA ESTIMADO PROMEDIO SOLO TERRENO | N35: VALOR VENTA ESTIMADO PROMEDIO CON CONSTRUCCIONES | AB35: VALOR VENTA ESTIMADO PROMEDIO CON CONSTRUCCIONES Y C. ACCESORIAS
A37: MÁXIMO sugerido | D37: =D39*1.1 -> #VALUE! | N37: MÁXIMO | Q37: =IF(EXACT(Q39, "N/A"), Q39, Q39*1.1) -> N/A | AB37: MÁXIMO sugerido | AE37: =IF(EXACT(AE39, "N/A"), AE39, AE39*1.1) -> N/A
A39: MEDIO o justo | D39: =ROUND(AI150,-3) -> #VALUE! | N39: MEDIO | Q39: =IF(K115=0, "N/A", ROUND(AJ111+AJ123+AJ148, -3)) -> N/A | AB39: MEDIO o justo | AE39: =IF(J145=0, "N/A", ROUND(AJ111+AJ123+AJ145+AJ148, -3)) -> N/A
A41: MÍNIMO sugerido | D41: =D39*0.9 -> #VALUE! | N41: MÍNIMO | Q41: =IF(EXACT(Q39, "N/A"), Q39, Q39*0.9) -> N/A | AB41: MÍNIMO sugerido | AE41: =IF(EXACT(AE39, "N/A"), AE39, AE39*0.9) -> N/A
A45: FORMA | N45: USO DE SUELO | T45: =UPPER(K85) -> HABITACIONAL DENSIDAD MÍNIMA UNIFAMILIAR | AB45: CALIFICA CRÉDITO
AB46: para bancos, infonavit, fovisste
A47: TOPOGRAFÍA | N47: UBICACIÓN EN MANZANA | R47: =V92
A49: FRENTES A CALLE | G49: =Query_Formato!B70 -> 1 | N49: VISTAS | AB49: PLUSVALÍA ANUAL
A51: SUP. TERRENO | I51: =G111 -> 0 | N51: TIPO DE TERRENO | AB51: CERCANÍA
A53: SUP. CONSTRUCCIONES | I53: =K123 -> 0 | N53: NUM. LADOS | S53: =Query_Formato!B69 -> 4 | AB53: DEMANDA DE LA ZONA
A54: vendibles
N55: VALOR RENTA ESTIMADO CON CONSTRUCCIONES
A56: TASA RENTA ANUAL | I56: =(AP152*10)/1 -> 0.04
N57: MÁXIMO | Q57: =Q59*1.1 -> #DIV/0!
A58: VALOR ESTIMADO POR M2 TERRENO | I58: =AC108 -> #DIV/0!
N59: MEDIO | Q59: =AJ152 -> #DIV/0!
N61: MÍNIMO | Q61: =Q59*0.9 -> #DIV/0!
A73: CARACTERÍSTICAS URBANAS Y DEL INMUEBLE
A75: CUENTA PREDIAL: | S75: CLAVE CATASTRAL:
A77: OBJETO DEL ANÁLISIS: | X77: RÉGIMEN DE PROP:
A79: SERVICIOS: | K79: =+CONCATENATE(AQ90," ",AR90,", ",AQ91," ",AR91,", ",AQ92," ",AR92,", ",AQ93," ",AR93,", ",AQ94," ",AR94,", ",AQ95," ",AR95,", ",AQ96," ",AR96,", ",AQ97," ",AR97,", ",AQ98," ",AR98,".", ) -> SERVICIOS BÁSICOS: , AGUA POTABLE: , DRENAJE: , ENERGÍA ELÉCTRICA: , GAS: , ALUMBRADO EXTERIOR: , LÍNEAS TELEFÓNICAS: , VIALIDADES: , TRANSPORTE: .
A82: CLASIFICACIÓN DE LA ZONA:
V84: C.O.S. | X84: C.U.S. | AA84: Fr Min | AC84: M2 Min. Lote | AF84: N° Est. | AH84: % Edif. Zona | AK84: % EDIF. SUJETO | AP84: AÑO DE CONSTR. | AQ84: 1995
A85: USO DEL SUELO: | F85: H1-U | K85: =UPPER(CONCATENATE(VLOOKUP(F85,'catalogo 2'!L5:N103,2,0)," ",(VLOOKUP(F85,'catalogo 2'!L5:N103,3,0)))) -> HABITACIONAL DENSIDAD MÍNIMA UNIFAMILIAR | V85: =VLOOKUP(F85,'catalogo 2'!L4:AI84,14,0) -> 0.4 | X85: =VLOOKUP(F85,'catalogo 2'!L4:AI84,16,0) -> 0.8 | AA85: =VLOOKUP(F85,'catalogo 2'!L4:AI84,11,0) -> 20 | AC85: =VLOOKUP(F85,'catalogo 2'!L4:AI84,10,0) -> 600 m2 | AF85: =VLOOKUP(F85,'catalogo 2'!L4:AI84,18,0) -> 4
A87: EDAD APROX. | F87: VIDA ÚTIL | I87: ED. REMANENTE | M87: EDAD TIPO | R87: CALIDAD | V87: CONSERVACIÓN | AA87: TOPOGRAFIA | AH87: CLAVE | AL87: % EDIF.
A88: =YEAR(TODAY()) - AQ84 -> 31 | F88: 60 | I88: =+F88-A88 -> 29 | M88: =VLOOKUP(A88,'catalogo 2'!C113:F118,4) -> #N/A | AG88: =+CONCATENATE(VLOOKUP(M88,'catalogo 2'!E120:F125,2,FALSE),".",VLOOKUP('OPI Constr'!R80,'catalogo 2'!G120:H125,2,FALSE),".",VLOOKUP('OPI Constr'!V80,'catalogo 2'!I120:J128,2,FALSE),".",VLOOKUP('OPI Constr'!Z80,'catalogo 2'!L120:M129,2,FALSE)) -> #N/A | AO88: SELECCIONAR SERVICIOS DE LA ZONA
A90: MEDIDAS Y LINDEROS SEGÚN: | Z90: =VLOOKUP("3.jp*g",Fotos!$A$2:$E395,5,FALSE) | AQ90: SERVICIOS BÁSICOS:
AQ91: AGUA POTABLE:
A92: Norte | AQ92: DRENAJE:
A93: =IF($A$92="norte","Sur","Sureste") -> Sur | E93: =IF(E92<>"", E92, "") | AQ93: ENERGÍA ELÉCTRICA:
A94: =IF($A$92="norte","Este","Noroeste") -> Este | AQ94: GAS:
...

Sheet OPI Terreno Rta
AF1: 3314189492 | AI1: 3336320507
AF2: avaluos@avaluosyarquitectura.com.mx
O3: OPINIÓN DE VALOR | AF3: avaluosyarquitectura2@gmail.com
AF4: www.avaluosyarquitectura.com.mx
C7: FOLIO | G7: =Query_Formato!D169 | AA7: Fecha: | AD7: =TODAY() -> 46202
A9: OPINIÓN DE VALOR DE:
A11: UBICACIÓN: | J11: =Query_Formato!B9 -> Pascal 2164 Colonia San Elias Guadalajara Jalisco 44240
A14: SOLICITANTE:
A16: PROPIETARIO: | J16: =J14
A18: =Fotos!E1 -> Foto | T18: =Fotos!E2
AB65: SOLO TERRENO | AD65: =+AI161 -> #REF!
AB67: CON CONSTRUCCIONES | AD67: =+AJ119+AJ131 -> #REF!
AB69: CON CONSTRUCCIONES ACCESORIAS | AD69: =+AJ158 -> #REF!
A71: ANTECEDENTES
A73: SOLICITANTE: | K73: =J14
A75: UBICACIÓN: | K75: =J11 -> Pascal 2164 Colonia San Elias Guadalajara Jalisco 44240
A77: CUENTA PREDIAL: | K77: No proporcionado | S77: CLAVE CATASTRAL: | AA77: 070-01-71-00-414-006-000-00-00
A79: INMUEBLE: | K79: =J9
A80: PROPIETARIO: | K80: =J16
A82: OBJETO DEL ANÁLISIS: | K82: Estimar el Valor Comercial | X82: RÉGIMEN DE PROP: | AD82: Privada en condominio
A84: CARACTERÍSTICAS URBANAS Y DEL INMUEBLE
A86: SERVICIOS: | K86: =+CONCATENATE(AQ97," ",AR97,", ",AQ98," ",AR98,", ",AQ99," ",AR99,", ",AQ100," ",AR100,", ",AQ101," ",AR101,", ",AQ102," ",AR102,", ",AQ103," ",AR103,", ",AQ104," ",AR104,", ",AQ105," ",AR105,".", ) -> SERVICIOS BÁSICOS: , AGUA POTABLE: , DRENAJE: , ENERGÍA ELÉCTRICA: , GAS: , ALUMBRADO EXTERIOR: , LÍNEAS TELEFÓNICAS: , VIALIDADES: , TRANSPORTE: .
A89: CLASIFICACIÓN DE LA ZONA:
V91: C.O.S. | X91: C.U.S. | Z91: Fr Min | AC91: M2 Min. Lote | AF91: N° Est. | AQ91: 1995
A92: USO DEL SUELO: | K92: =UPPER(CONCATENATE(VLOOKUP(F91,'catalogo 2'!L6:N104,2,0)," ",(VLOOKUP(F91,'catalogo 2'!L6:N104,3,0)))) -> #REF! | V92: 0.8 | X92: 1.6 | Z92: 6 | AC92: 90 m2 | AF92: 1
A94: EDAD APROX. | F94: VIDA ÚTIL | I94: ED. REMANENTE | M94: EDAD TIPO | R94: CALIDAD | V94: CONSERVACIÓN | AA94: PROYECTO: | AH94: CLAVE | AL94: % EDIF.
A95: =YEAR(TODAY()) - AQ91 -> 31 | F95: 60 | I95: =+F95-A95 -> 29 | M95: =VLOOKUP(A95,'catalogo 2'!C128:F133,4) -> #REF! | AG95: =+CONCATENATE(VLOOKUP(M95,'catalogo 2'!E135:F140,2,FALSE),".",VLOOKUP('OPI Constr'!R94,'catalogo 2'!G135:H140,2,FALSE),".",VLOOKUP('OPI Constr'!V94,'catalogo 2'!I135:J143,2,FALSE),".",VLOOKUP('OPI Constr'!Z94,'catalogo 2'!L135:M144,2,FALSE)) -> #REF! | AO95: SELECCIONAR SERVICIOS DE LA ZONA
A97: MEDIDAS Y LINDEROS SEGÚN: | X97: =#REF! -> #REF! | AQ97: SERVICIOS BÁSICOS:
AQ98: AGUA POTABLE:
A99: Norte | AQ99: DRENAJE:
A100: =IF($A$99="norte","Sur","Sureste") -> Sur | E100: =IF(E99<>"", E99, "") | AQ100: ENERGÍA ELÉCTRICA:
A101: =IF($A$99="norte","Este","Noroeste") -> Este | AQ101: GAS:
A102: =IF($A$99="norte","Oeste","Suroeste") -> Oeste | E102: =IF(E101<>"", E101, "") | AQ102: ALUMBRADO EXTERIOR:
AQ103: LÍNEAS TELEFÓNICAS:
A104: DESCRIPCIÓN DEL INMUEBLE | AQ104: VIALIDADES:
AQ105: TRANSPORTE:
A112: AVALÚO FÍSICO
C113: A) DEL TERRENO: | P113: LOTE TIPO: | Q113: VARIABLE
A114: FRACC. | C114: SUPERFICIE: | G114: SUPERFICIE M2 | K114: VALOR UNITARIO | L114: FACTORES DE EFICIENCIA DE SUELO: | AC114: V. TERRENO | AG114: INDIVISO: | AJ114: VALOR
L115: ZONA | N115: UBICA | P115: FRENTE | R115: FORMA | T115: SUPERFICIE | X115: TOPOGRAF. | Z115: FAC.RE. | AC115: RESULTANTE: | AJ115: RESULTANTE:
...

Sheet OPI Rentas
AF1: 3314189492 | AI1: 3336320507
O2: OPINIÓN DE VALOR RENTA | AF2: avaluos@avaluosyarquitectura.com.mx
AF3: avaluosyarquitectura2@gmail.com
AF4: www.avaluosyarquitectura.com.mx
A6: FOLIO | E6: =Query_Formato!B168 -> OPI-25-11-07-OF | AF6: Fecha: | AG6: =TODAY() -> 46202
A8: TIPO DE PROPIEDAD: | Y8: SOLICITANTE: | Z8: =Query_Formato!B156 -> Federico Arellano
A10: UBICACIÓN: | E10: =Query_Formato!B9 -> Pascal 2164 Colonia San Elias Guadalajara Jalisco 44240 | Y10: PROPIETARIO:
A13: =VLOOKUP("1.jp*g",Fotos!$A$2:$E444,5,FALSE) | V13: =VLOOKUP("2.jp*g",Fotos!$A$2:$E444,5,FALSE)
A34: RESUMEN
A36: VALOR RENTA ESTIMADO PROMEDIO | N36: VALOR DE RENTA ESTIMADO PROMEDIO | AB36: REPRESENTATIVA DEL VALOR FÍSICO
A38: MÁXIMO sugerido | D38: =D40*1.1 -> #DIV/0! | N38: MÁXIMO | Q38: =Q40*1.1 -> #DIV/0! | AB38: TERRENO | AI38: =AN111 -> #DIV/0!
AB39: CONSTRUCCIONES | AI39: =AN123 -> #DIV/0!
A40: MEDIO o justo | D40: =ROUND(AJ161,3) -> #DIV/0! | N40: MEDIO | Q40: =ROUND(AI166,3) -> #DIV/0! | AB40: CONSTR. ACCESORIAS | AI40: =AN135 -> #DIV/0!
A42: MÍNIMO sugerido | D42: =D40*0.9 -> #DIV/0! | N42: MÍNIMO | Q42: =Q40*0.9 -> #DIV/0! | AB42: INSTALACIONES ACCESORIAS | AI42: =AN157 -> #DIV/0!
AI43: tot | AJ43: =SUM(AI38:AI43) -> #DIV/0!
A46: UNIDADES RENTABLES | K46: =AD80 | N46: TASA RENTA ANUAL | W46: =(AP166*10)/1 -> 0.04 | AB46: CALIFICA CRÉDITO
A48: NIVELES | I48: =AK86 | N48: ESTADO DE CONSERVACIÓN | X48: =W86
A50: NIVEL UBICACIÓN | H50: =AG86 | N50: EDAD PONDERADA APROX | W50: =A86 -> 7 | AB50: PLUSVALÍA ANUAL
A52: TERRENO | I52: =C111 -> 0 | N52: EDAD REMANENTE | W52: =I86 -> 53 | AB52: CERCANÍA
A54: CONSTRUCCIONES | I54: =K123 -> 0 | N54: AVANCE DE OBRA | W54: =AJ83 | AB54: DEMANDA DE LA ZONA
A55: vendibles
A56: RESUMEN DE ESPACIOS
B58: RESUMEN ESPACIOS BÁSICOS | P58: ELEMENTOS ACCESORIOS | AC58: AMENIDADES DEL CONJUNTO
A59: =IF(B59<>"", IF((COUNTIFS($AP$92:$AP$109, "*"&B59&"*") + COUNTIFS($AR$92:$AR$109, "*"&B59&"*")) > 0, SUMIFS($AO$92:$AO$109, $AP$92:$AP$109, "*"&B59&"*") + SUMIFS($AQ$92:$AQ$109, $AR$92:$AR$109, "*"&B59&"*") + SUMIFS($AT$92:$AT$109, $AU$92:$AU$109, "*"&B59&"*") + SUMIFS($AV$92:$AV$109, $AW$92:$AW$109, "*"&B59&"*"), ""), "") | B59: ESTACIONAMIENTOS | M59: =J140 | O59: =+UPPER(C140)
A60: =IF(B60<>"", IF((COUNTIFS($AP$92:$AP$109, "*"&B60&"*") + COUNTIFS($AR$92:$AR$109, "*"&B60&"*")) > 0, SUMIFS($AO$92:$AO$109, $AP$92:$AP$109, "*"&B60&"*") + SUMIFS($AQ$92:$AQ$109, $AR$92:$AR$109, "*"&B60&"*") + SUMIFS($AT$92:$AT$109, $AU$92:$AU$109, "*"&B60&"*") + SUMIFS($AV$92:$AV$109, $AW$92:$AW$109, "*"&B60&"*"), ""), "") | B60: COCINA | M60: =J141 | O60: =+UPPER(C141)
A61: =IF(B61<>"", IF((COUNTIFS($AP$92:$AP$109, "*"&B61&"*") + COUNTIFS($AR$92:$AR$109, "*"&B61&"*")) > 0, SUMIFS($AO$92:$AO$109, $AP$92:$AP$109, "*"&B61&"*") + SUMIFS($AQ$92:$AQ$109, $AR$92:$AR$109, "*"&B61&"*"), ""), "") | B61: PATIO | M61: =J142 | O61: =+UPPER(C142)
A62: =IF(B62<>"", IF((COUNTIFS($AP$92:$AP$109, "*"&B62&"*") + COUNTIFS($AR$92:$AR$109, "*"&B62&"*")) > 0, SUMIFS($AO$92:$AO$109, $AP$92:$AP$109, "*"&B62&"*") + SUMIFS($AQ$92:$AQ$109, $AR$92:$AR$109, "*"&B62&"*") + SUMIFS($AT$92:$AT$109, $AU$92:$AU$109, "*"&B62&"*") + SUMIFS($AV$92:$AV$109, $AW$92:$AW$109, "*"&B62&"*"), ""), "") | B62: RECAMARAS | M62: =J143 | O62: =+UPPER(C143)
A63: =IF(B63<>"", IF((COUNTIFS($AP$92:$AP$109, "*"&B63&"*") + COUNTIFS($AR$92:$AR$109, "*"&B63&"*")) > 0, SUMIFS($AO$92:$AO$109, $AP$92:$AP$109, "*"&B63&"*") + SUMIFS($AQ$92:$AQ$109, $AR$92:$AR$109, "*"&B63&"*") + SUMIFS($AT$92:$AT$109, $AU$92:$AU$109, "*"&B63&"*") + SUMIFS($AV$92:$AV$109, $AW$92:$AW$109, "*"&B63&"*"), ""), "") | B63: BAÑOS | M63: =J144 | O63: =+UPPER(C144)
A64: =IF(B64<>"", IF((COUNTIFS($AP$92:$AP$109, "*"&B64&"*") + COUNTIFS($AR$92:$AR$109, "*"&B64&"*")) > 0, SUMIFS($AO$92:$AO$109, $AP$92:$AP$109, "*"&B64&"*") + SUMIFS($AQ$92:$AQ$109, $AR$92:$AR$109, "*"&B64&"*") + SUMIFS($AT$92:$AT$109, $AU$92:$AU$109, "*"&B64&"*") + SUMIFS($AV$92:$AV$109, $AW$92:$AW$109, "*"&B64&"*"), ""), "") | M64: =J145 | O64: =+UPPER(C145)
A65: =IF(B65<>"", IF((COUNTIFS($AP$92:$AP$109, "*"&B65&"*") + COUNTIFS($AR$92:$AR$109, "*"&B65&"*")) > 0, SUMIFS($AO$92:$AO$109, $AP$92:$AP$109, "*"&B65&"*") + SUMIFS($AQ$92:$AQ$109, $AR$92:$AR$109, "*"&B65&"*") + SUMIFS($AT$92:$AT$109, $AU$92:$AU$109, "*"&B65&"*") + SUMIFS($AV$92:$AV$109, $AW$92:$AW$109, "*"&B65&"*"), ""), "") | M65: =J146 | O65: =+UPPER(C146)
A66: =IF(B66<>"", IF((COUNTIFS($AP$92:$AP$109, "*"&B66&"*") + COUNTIFS($AR$92:$AR$109, "*"&B66&"*")) > 0, SUMIFS($AO$92:$AO$109, $AP$92:$AP$109, "*"&B66&"*") + SUMIFS($AQ$92:$AQ$109, $AR$92:$AR$109, "*"&B66&"*") + SUMIFS($AT$92:$AT$109, $AU$92:$AU$109, "*"&B66&"*") + SUMIFS($AV$92:$AV$109, $AW$92:$AW$109, "*"&B66&"*"), ""), "") | M66: =J147 | O66: =+UPPER(C147)
A67: =IF(B67<>"", IF((COUNTIFS($AP$92:$AP$109, "*"&B67&"*") + COUNTIFS($AR$92:$AR$109, "*"&B67&"*")) > 0, SUMIFS($AO$92:$AO$109, $AP$92:$AP$109, "*"&B67&"*") + SUMIFS($AQ$92:$AQ$109, $AR$92:$AR$109, "*"&B67&"*") + SUMIFS($AT$92:$AT$109, $AU$92:$AU$109, "*"&B67&"*") + SUMIFS($AV$92:$AV$109, $AW$92:$AW$109, "*"&B67&"*"), ""), "") | M67: =J148 | O67: =+UPPER(C148)
AP69: AÑO ACTUAL | AQ69: 2024
A70: CARACTERÍSTICAS URBANAS Y DEL INMUEBLE
AP71: AÑO DE CONSTR. | AQ71: 2019
A72: CUENTA PREDIAL: | H72: =Query_Formato!B31 | O72: CLAVE CATASTRAL: | T72: =Query_Formato!B30 | Z72: MUNICIPIO | AB72: =Query_Formato!K30 | AP72: EDAD | AQ72: =+AQ69-AQ71 -> 5
A74: OBJETO DEL ANÁLISIS: | S74: RÉGIMEN DE PROP: | AF74: COLONIA
AO75: SELECCIONAR SERVICIOS DE LA ZONA
A77: SERVICIOS: | H77: =+CONCATENATE(AQ77," ",AR77,", ",AQ78," ",AR78,", ",AQ79," ",AR79,", ",AQ80," ",AR80,", ",AQ81," ",AR81,", ",AQ82," ",AR82,", ",AQ83," ",AR83,", ",AQ84," ",AR84,", ",AQ85," ",AR85,".", ) -> SERVICIOS BÁSICOS: , AGUA POTABLE: , DRENAJE: , ENERGÍA ELÉCTRICA: , GAS: , ALUMBRADO EXTERIOR: , LÍNEAS TELEFÓNICAS: , VIALIDADES: , TRANSPORTE: . | AQ77: SERVICIOS BÁSICOS:
AQ78: AGUA POTABLE:
...

Sheet OPI Constr
AF1: 3314189492 | AI1: 3336320507
O2: OPINIÓN DE VALOR | AF2: avaluos@avaluosyarquitectura.com.mx
AF3: avaluosyarquitectura2@gmail.com
AF4: www.avaluosyarquitectura.com.mx
A6: FOLIO | E6: =Query_Formato!B168 -> OPI-25-11-07-OF | AF6: Fecha: | AG6: =TODAY() -> 46202
A8: TIPO DE PROPIEDAD: | E8: =Query_Formato!B44 -> Casa Habitación | Y8: SOLICITANTE: | Z8: =Query_Formato!B156 -> Federico Arellano
A10: UBICACIÓN: | E10: Pascal 2164, San Elías, 44246 Guadalajara, Jal. | Y10: PROPIETARIO: | Z10: Datos No Proporcionados
A13: =VLOOKUP("1.jp*g",Fotos!$A$2:$E371,5,FALSE) | V13: =VLOOKUP("2.jp*g",Fotos!$A$2:$E371,5,FALSE)
A34: RESUMEN
A36: VALOR VENTA ESTIMADO PROMEDIO | N36: VALOR DE RENTA ESTIMADO PROMEDIO | AB36: REPRESENTATIVA DEL VALOR FÍSICO
A38: MÁXIMO sugerido | D38: =D40*1.1 -> 2676300 | N38: MÁXIMO | Q38: =Q40*1.1 -> 11000 | AB38: TERRENO | AI38: =AN111 -> 0.53348441
AB39: CONSTRUCCIONES | AI39: =AN123 -> 0.46183497
A40: MEDIO o justo | D40: =AI165 -> 2433000 | N40: MEDIO | Q40: =ROUND(AI166,-3) -> 10000 | AB40: CONSTR. ACCESORIAS | AI40: =AN135 -> 0
A42: MÍNIMO sugerido | D42: =D40*0.9 -> 2189700 | N42: MÍNIMO | Q42: =Q40*0.9 -> 9000 | AB42: INSTALACIONES ACCESORIAS | AI42: =AN157 -> 0.0046806206
AI43: tot | AJ43: =SUM(AI38:AI43) -> 1
A46: UNIDADES RENTABLES | K46: =AE80 -> 1 | N46: TASA RENTA ANUAL | W46: =(AP166*10)/1 -> 0.04 | AB46: CALIFICA CRÉDITO | AH46: SI
AB47: para bancos, infonavit, fovisste, instituciones financieras
A48: NIVELES | I48: =AK86 -> 1 | N48: ESTADO DE CONSERVACIÓN | X48: =W86 -> REMODELADO
A50: NIVEL UBICACIÓN | H50: =AG86 -> 0 - P.BAJA | N50: EDAD PONDERADA APROX | W50: =A86 -> 21 | AB50: PLUSVALÍA ANUAL | AI50: 4-6%
A52: TERRENO | I52: =C111 -> 91.97 | N52: EDAD REMANENTE | W52: =I86 -> 49 | AB52: CERCANÍA | AG52: INTERMEDIA
A54: CONSTRUCCIONES | I54: =K123 -> 74.2 | N54: AVANCE DE OBRA | W54: =AJ83 -> 1 | AB54: DEMANDA DE LA ZONA | AG54: MEDIA
A55: vendibles
A56: RESUMEN DE ESPACIOS
B58: RESUMEN ESPACIOS BÁSICOS | P58: ELEMENTOS ACCESORIOS | AC58: AMENIDADES DEL CONJUNTO
A59: =IF(B59<>"", IF((COUNTIFS($AP$92:$AP$109, "*"&B59&"*") + COUNTIFS($AR$92:$AR$109, "*"&B59&"*")) > 0, SUMIFS($AO$92:$AO$109, $AP$92:$AP$109, "*"&B59&"*") + SUMIFS($AQ$92:$AQ$109, $AR$92:$AR$109, "*"&B59&"*") + SUMIFS($AT$92:$AT$109, $AU$92:$AU$109, "*"&B59&"*") + SUMIFS($AV$92:$AV$109, $AW$92:$AW$109, "*"&B59&"*"), ""), "") -> 1 | B59: SALA | O59: NO TIENE | AB59: NO TIENE
A60: =IF(B60<>"", IF((COUNTIFS($AP$92:$AP$109, "*"&B60&"*") + COUNTIFS($AR$92:$AR$109, "*"&B60&"*")) > 0, SUMIFS($AO$92:$AO$109, $AP$92:$AP$109, "*"&B60&"*") + SUMIFS($AQ$92:$AQ$109, $AR$92:$AR$109, "*"&B60&"*") + SUMIFS($AT$92:$AT$109, $AU$92:$AU$109, "*"&B60&"*") + SUMIFS($AV$92:$AV$109, $AW$92:$AW$109, "*"&B60&"*"), ""), "") -> 1 | B60: COCINA | E60: COMERCIAL | I60: MINIMA | M60: =J141 | AB60: =+UPPER(C141)
A61: =IF(B61<>"", IF((COUNTIFS($AP$92:$AP$109, "*"&B61&"*") + COUNTIFS($AR$92:$AR$109, "*"&B61&"*")) > 0, SUMIFS($AO$92:$AO$109, $AP$92:$AP$109, "*"&B61&"*") + SUMIFS($AQ$92:$AQ$109, $AR$92:$AR$109, "*"&B61&"*"), ""), "") -> 1 | B61: PATIO | M61: =J142 | O61: =+UPPER(C142)
A62: =IF(B62<>"", IF((COUNTIFS($AP$92:$AP$109, "*"&B62&"*") + COUNTIFS($AR$92:$AR$109, "*"&B62&"*")) + COUNTIFS($AU$92:$AUR$109, "*"&B62&"*") > 0, SUMIFS($AO$92:$AO$109, $AP$92:$AP$109, "*"&B62&"*") + SUMIFS($AQ$92:$AQ$109, $AR$92:$AR$109, "*"&B62&"*") + SUMIFS($AT$92:$AT$109, $AU$92:$AU$109, "*"&B62&"*") + SUMIFS($AV$92:$AV$109, $AW$92:$AW$109, "*"&B62&"*"), ""), "") -> 3 | B62: RECAMARAS | M62: =J143 | O62: =+UPPER(C143)
A63: =IF(B63<>"", IF((COUNTIFS($AP$92:$AP$109, "*"&B63&"*") + COUNTIFS($AR$92:$AR$109, "*"&B63&"*")) > 0, SUMIFS($AO$92:$AO$109, $AP$92:$AP$109, "*"&B63&"*") + SUMIFS($AQ$92:$AQ$109, $AR$92:$AR$109, "*"&B63&"*") + SUMIFS($AT$92:$AT$109, $AU$92:$AU$109, "*"&B63&"*") + SUMIFS($AV$92:$AV$109, $AW$92:$AW$109, "*"&B63&"*"), ""), "") -> 2 | B63: BAÑOS | M63: =J144 | O63: =+UPPER(C144)
A64: =IF(B64<>"", IF((COUNTIFS($AP$92:$AP$109, "*"&B64&"*") + COUNTIFS($AR$92:$AR$109, "*"&B64&"*")) > 0, SUMIFS($AO$92:$AO$109, $AP$92:$AP$109, "*"&B64&"*") + SUMIFS($AQ$92:$AQ$109, $AR$92:$AR$109, "*"&B64&"*") + SUMIFS($AT$92:$AT$109, $AU$92:$AU$109, "*"&B64&"*") + SUMIFS($AV$92:$AV$109, $AW$92:$AW$109, "*"&B64&"*"), ""), "") | B64: . | M64: =J145 | O64: =+UPPER(C145)
A65: =IF(B65<>"", IF((COUNTIFS($AP$92:$AP$109, "*"&B65&"*") + COUNTIFS($AR$92:$AR$109, "*"&B65&"*")) > 0, SUMIFS($AO$92:$AO$109, $AP$92:$AP$109, "*"&B65&"*") + SUMIFS($AQ$92:$AQ$109, $AR$92:$AR$109, "*"&B65&"*") + SUMIFS($AT$92:$AT$109, $AU$92:$AU$109, "*"&B65&"*") + SUMIFS($AV$92:$AV$109, $AW$92:$AW$109, "*"&B65&"*"), ""), "") | M65: =J146 | O65: =+UPPER(C146)
A66: =IF(B66<>"", IF((COUNTIFS($AP$92:$AP$109, "*"&B66&"*") + COUNTIFS($AR$92:$AR$109, "*"&B66&"*")) > 0, SUMIFS($AO$92:$AO$109, $AP$92:$AP$109, "*"&B66&"*") + SUMIFS($AQ$92:$AQ$109, $AR$92:$AR$109, "*"&B66&"*") + SUMIFS($AT$92:$AT$109, $AU$92:$AU$109, "*"&B66&"*") + SUMIFS($AV$92:$AV$109, $AW$92:$AW$109, "*"&B66&"*"), ""), "") | M66: =J147 | O66: =+UPPER(C147)
A67: =IF(B67<>"", IF((COUNTIFS($AP$92:$AP$109, "*"&B67&"*") + COUNTIFS($AR$92:$AR$109, "*"&B67&"*")) > 0, SUMIFS($AO$92:$AO$109, $AP$92:$AP$109, "*"&B67&"*") + SUMIFS($AQ$92:$AQ$109, $AR$92:$AR$109, "*"&B67&"*") + SUMIFS($AT$92:$AT$109, $AU$92:$AU$109, "*"&B67&"*") + SUMIFS($AV$92:$AV$109, $AW$92:$AW$109, "*"&B67&"*"), ""), "") | M67: =J148 | O67: =+UPPER(C148)
AP69: AÑO ACTUAL | AQ69: 2025
A70: CARACTERÍSTICAS URBANAS Y DEL INMUEBLE
AP71: AÑO DE CONSTR. | AQ71: 2005
A72: CUENTA PREDIAL: | H72: Datos No Proporcionados | O72: CLAVE CATASTRAL: | S72: Datos No Proporcionados | Z72: MUNICIPIO | AB72: Guadalajara | AP72: EDAD | AQ72: =+AQ69-AQ71 -> 20
A74: OBJETO DEL ANÁLISIS: | H74: Estimar el Valor Comercial | S74: RÉGIMEN DE PROP: | W74: Privada | AF74: COLONIA | AG74: San Elías
AO75: SELECCIONAR SERVICIOS DE LA ZONA
A77: SERVICIOS: | H77: =+CONCATENATE(AQ77," ",AR77,", ",AQ78," ",AR78,", ",AQ79," ",AR79,", ",AQ80," ",AR80,", ",AQ81," ",AR81,", ",AQ82," ",AR82,", ",AQ83," ",AR83,", ",AQ84," ",AR84,", ",AQ85," ",AR85,".", ) -> SERVICIOS BÁSICOS: COMPLETOS, AGUA POTABLE: ENTUBADA, DRENAJE: ENTUBADO, ENERGÍA ELÉCTRICA: CON CABLEADO AÉREO, CON CILINDROS, ALUMBRADO EXTERIOR: CON CABLEADO AÉREO, LÍNEAS TELEFÓNICAS: CON CABLEADO AÉREO, VIALIDADES: DE ASFALTO, TRANSPORTE: URBANO. | AQ77: SERVICIOS BÁSICOS: | AR77: COMPLETOS
...

Sheet Formulario Rta
A1: TIEMPO RENTA | B1: OCUPACION | C1: SEXO | D1: EDAD | E1: PROCEDENCIA | F1: INGRESOS | G1: INTERES | H1: TRANSPORTE | I1: CERCANIA | J1: BAÑO | K1: PREFERENCIAS | L1: HORARIOS | M1: TOPE PRESUPUESTO | N1: NOMBRE | O1: CONTACTO

Sheet Estructura Formulario
A1: Form Title: | B1: Description: | C1: URL Formulario Edición | D1: URL Formulario Producción
A2: Esto es una prueba | B2: Esto es otra prueba | C2: https://docs.google.com/forms/d/1jOj5Q_ITljql8OtieIXmQVCeRM0Epbu7PfoN4C9rKQI/edit | D2: https://forms.gle/VXjT7o5P9uFxPA2bA
E3: Opciones
A4: Tipo Pregunta | B4: Descripción de la Pregunta | C4: Tipo Atributo | D4: Opción Requerida ? | E4: Op1 | F4: Op2 | G4: Op3 | H4: Op4 | I4: Op5 | J4: Op6 | K4: Op7
A5: TIEMPO RENTA | B5: Prueba | C5: Texto | D5: TRUE
A6: OCUPACION | B6: Prueba | C6: Texto | D6: TRUE
A7: SEXO | B7: Prueba | C7: Texto | D7: TRUE
A8: EDAD | B8: Prueba | C8: Varias Opciones | D8: TRUE | E8: aSD | F8: ASDA
A9: PROCEDENCIA | B9: Prueba | C9: Texto | D9: TRUE
A10: INGRESOS | B10: Prueba | C10: Desplegable | D10: TRUE | E10: DASDQ32 | F10: 213ESAD | G10: WSDAS2 | H10: 21E
A11: INTERES | B11: Prueba | C11: Parrafo | D11: FALSE
A12: TRANSPORTE | B12: Prueba | C12: Parrafo | D12: FALSE
A13: CERCANIA | B13: Prueba | C13: Parrafo | D13: FALSE
A14: BAÑO | B14: Prueba | C14: Parrafo | D14: FALSE
A15: PREFERENCIAS | B15: Prueba | C15: Parrafo | D15: FALSE
A16: HORARIOS | B16: Prueba | C16: Parrafo | D16: FALSE
A17: TOPE PRESUPUESTO | B17: Prueba | C17: Casilla | D17: FALSE | E17: DASD2E | F17: QWD21EDAS | G17: Q2E21EDQW | H17: ASD2E12 | I17: AD2ER12
A18: NOMBRE | B18: Prueba | C18: Parrafo | D18: FALSE
A19: CONTACTO | B19: Prueba | C19: Parrafo | D19: FALSE

Sheet Mercado
A2: ESTUDIO DE MERCADO DE VENTAS TERRENOS | H2: COMPARABLES DE VENTA
A3: Fecha | B3: ESTATUS COMERCIAL: | C3: TIPO: | D3: CIUDAD | E3: Colonia | F3: DIRECCIÓN: | G3: COMENT: | H3: TERRENO | I3: CONST | J3: PRECIO: | K3: $ por m2 | L3: FUENTE: | M3: TELÉFONO: | N3: LINK:
B4: VENTA | C4: ='OPI Terreno'!E8 | E4: Rancho Nuevo 1ra. Sección | H4: 365 | J4: 3150000 | K4: =J4/H4 -> 8630.137 | N4: https://www.casasyterrenos.com/propiedad/terreno-venta-eutimio-pinzon-rancho-nuevo-1ra-seccion-guadalajara-jal-3779336
B5: =+B4 -> VENTA | C5: =C4
B6: =+B5 -> VENTA | C6: =C5 | E6: Independencia | H6: 200 | J6: 2400000 | K6: =J6/H6 -> 12000 | N6: https://www.inmuebles24.com/propiedades/clasificado/vecltein-venta-de-terreno-en-colonia-independencia-147013498.html?n_src=Listado&n_exp=trigger_pills-original&n_pg=1&n_pos=1
B7: =+B6 -> VENTA | C7: =C6
B8: =+B7 -> VENTA | C8: =C7
B9: =+B8 -> VENTA | K9: =+AVERAGE(K4,K5,K6,K7,K8) -> 10315.068
A11: OTROS COMPARABLES DE TERRENO
K12: =J12/H12 -> #DIV/0!
K13: =J13/H13 -> #DIV/0!
K14: =J14/H14 -> #DIV/0!
K15: =J15/H15 -> #DIV/0!
K16: =J16/H16 -> #DIV/0!
A18: ESTUDIO RESIDUAL DE TERRENO | H18: COMPARABLES DE VENTA
A19: Fecha | B19: ESTATUS COMERCIAL: | C19: TIPO: | D19: CIUDAD | E19: Colonia | F19: DIRECCIÓN: | G19: COMENT: | H19: TERRENO | I19: CONST | J19: PRECIO: | K19: EDAD | L19: ESTADO CONSERV. | M19: FACTOR | N19: $/M2 CONST. Usado | O19: VALOR CONST. | P19: VALOR TERRENO | Q19: $/M2 TERRENO
B20: VENTA | C20: =+'OPI Constr'!$E$8 -> Casa Habitación | D20: =D30 | E20: =E30 -> SAN ELIAS | F20: =F30 -> Avenida Fidel Velazquez 380 | G20: =G30 -> 1 Nivel 3 Recamaras con closet Cocina con alacenas estufas Área Sala-Comedor 1 Baño completo Patio amplio con Jardín | H20: =H30 -> 117 | I20: =I30 -> 71 | J20: =J30 -> 2700000 | K20: =L30 -> 40 | L20: Bueno | M20: =IF(L20<>"",VLOOKUP(K20,'Ross Heideke'!$A$6:$J$76,MATCH(L20,'Ross Heideke'!$B$5:$J$5,0),FALSE),"") -> 0.55084408 | N20: =+IF(M20<>"",'OPI Constr'!$N$115*$M20,"") -> 7436.3951 | O20: =+IF(N20<>"",N20*I20,"") -> 527984.05 | P20: =+IF(O20<>"",J20-O20,"") -> 2172015.9 | Q20: =+IF(P20<>"",P20/H20,"") -> 18564.239
B21: =+B20 -> VENTA | C21: =+C20 -> Casa Habitación | D21: =D31 | E21: =E31 -> INDEPENDENCIA | F21: =F31 -> Platón S/N | G21: =G31 -> 3 Recámaras 2 1/2 Baños 3 Cocheras Terraza al ingreso de la casa 1 Área de lavado Local comercial al frente de 35.00 mts con medio baño. | H21: =H31 -> 276 | I21: =I31 -> 193 | J21: =J31 -> 6600000 | K21: =L31 -> 30 | L21: Bueno | M21: =IF(L21<>"",VLOOKUP(K21,'Ross Heideke'!$A$6:$J$76,MATCH(L21,'Ross Heideke'!$B$5:$J$5,0),FALSE),"") -> 0.69365551 | N21: =+IF(M21<>"",'OPI Constr'!$N$115*$M21,"") -> 9364.3494 | O21: =+IF(N21<>"",N21*I21,"") -> 1807319.4 | P21: =+IF(O21<>"",J21-O21,"") -> 4792680.6 | Q21: =+IF(P21<>"",P21/H21,"") -> 17364.785 | Z21: =+(L30-20)/20 -> 1
B22: =+B21 -> VENTA | C22: =+C21 -> Casa Habitación | D22: =D32 | E22: =E32 -> Monumental | F22: =F32 -> Monumental S/N | G22: =G32 -> Cochera un auto, jardín exterior, sala comedor, cocina, patio de servicio, pasillo distribuidor, dos recámara secundarias cada una con su clóset que comparten un baño completo y otra principal con baño completo, jardín interior. | H22: =H32 -> 140 | I22: =I32 -> 103 | J22: =J32 -> 3790000 | K22: =L32 -> 6 | L22: Bueno | M22: =IF(L22<>"",VLOOKUP(K22,'Ross Heideke'!$A$6:$J$76,MATCH(L22,'Ross Heideke'!$B$5:$J$5,0),FALSE),"") -> 0.95316428 | N22: =+IF(M22<>"",'OPI Constr'!$N$115*$M22,"") -> 12867.718 | O22: =+IF(N22<>"",N22*I22,"") -> 1325374.9 | P22: =+IF(O22<>"",J22-O22,"") -> 2464625.1 | Q22: =+IF(P22<>"",P22/H22,"") -> 17604.465
B23: =+B22 -> VENTA | C23: =+C22 -> Casa Habitación | D23: =D33 | E23: =E33 -> Alcalde Barranquitas | F23: =F33 -> Avenida de los Maestros 576 | G23: =G33 -> 4 recámaras, 2 baños uso de suelo mixto, comercial y habitacional, cuarto de servicio con baño, área de lavandería | H23: =H33 -> 314 | I23: =I33 -> 201 | J23: =J33 -> 7500000 | K23: =L33 -> 40 | L23: Bueno | M23: =IF(L23<>"",VLOOKUP(K23,'Ross Heideke'!$A$6:$J$76,MATCH(L23,'Ross Heideke'!$B$5:$J$5,0),FALSE),"") -> 0.55084408 | N23: =+IF(M23<>"",'OPI Constr'!$N$115*$M23,"") -> 7436.3951 | O23: =+IF(N23<>"",N23*I23,"") -> 1494715.4 | P23: =+IF(O23<>"",J23-O23,"") -> 6005284.6 | Q23: =+IF(P23<>"",P23/H23,"") -> 19125.11
B24: =+B23 -> VENTA | C24: =+C23 -> Casa Habitación | D24: =D34 | E24: =E34 -> Independencia Oriente | F24: =F34 -> Los Alpes 1548 | G24: =G34 -> Sala y comedor Cocina integral 5 recámaras, 2 baños completos, Jardín lateral, espacio para 1 auto | H24: =H34 -> 175 | I24: =I34 -> 158 | J24: =J34 -> 4200000 | K24: =L34 -> 40 | L24: Bueno | M24: =IF(L24<>"",VLOOKUP(K24,'Ross Heideke'!$A$6:$J$76,MATCH(L24,'Ross Heideke'!$B$5:$J$5,0),FALSE),"") -> 0.55084408 | N24: =+IF(M24<>"",'OPI Constr'!$N$115*$M24,"") -> 7436.3951 | O24: =+IF(N24<>"",N24*I24,"") -> 1174950.4 | P24: =+IF(O24<>"",J24-O24,"") -> 3025049.6 | Q24: =+IF(P24<>"",P24/H24,"") -> 17285.998
B25: =+B24 -> VENTA | C25: =+C24 -> Casa Habitación | Q25: =+AVERAGE(Q20:Q24) -> 17988.919
A28: ESTUDIO DE MERCADO DE VENTAS CONSTRUCCIONES | H28: COMPARABLES DE VENTA
A29: Fecha | B29: ESTATUS COMERCIAL: | C29: TIPO: | D29: CIUDAD | E29: Colonia | F29: DIRECCIÓN: | G29: COMENT: | H29: TERRENO | I29: CONST | J29: PRECIO: | K29: $ por m2 | L29: EDAD: | M29: FUENTE: | N29: TELÉFONO: | O29: LINK:
B30: VENTA | C30: =+'OPI Constr'!$E$8 -> Casa Habitación | E30: SAN ELIAS | F30: Avenida Fidel Velazquez 380 | G30: 1 Nivel 3 Recamaras con closet Cocina con alacenas estufas Área Sala-Comedor 1 Baño completo Patio amplio con Jardín | H30: 117 | I30: 71 | J30: 2700000 | K30: =J30/I30 -> 38028.169 | L30: 40 | M30: GPM BIENES RAICES | N30: 33 1305 0083 | O30: https://www.inmuebles24.com/propiedades/clasificado/veclcain-casa-en-venta.-fraccionamiento-estadio-poniente-147959813.html?n_src=Listado&n_exp=trigger_pills-original&n_pg=1&n_pos=1
B31: =+B30 -> VENTA | C31: =+C30 -> Casa Habitación | E31: INDEPENDENCIA | F31: Platón S/N | G31: 3 Recámaras 2 1/2 Baños 3 Cocheras Terraza al ingreso de la casa 1 Área de lavado Local comercial al frente de 35.00 mts con medio baño. | H31: 276 | I31: 193 | J31: 6600000 | K31: =J31/I31 -> 34196.891 | L31: 30 | M31: Impacto Inmobiliaria | N31: 33 3485 2244 | O31: https://www.inmuebles24.com/propiedades/clasificado/veclcain-casa-en-venta-calle-platon-col.-independencia-146764086.html?n_src=Listado&n_exp=trigger_pills-original&n_pg=1&n_pos=1
B32: =+B31 -> VENTA | C32: =+C31 -> Casa Habitación | E32: Monumental | F32: Monumental S/N | G32: Cochera un auto, jardín exterior, sala comedor, cocina, patio de servicio, pasillo distribuidor, dos recámara secundarias cada una con su clóset que comparten un baño completo y otra principal con baño completo, jardín interior. | H32: 140 | I32: 103 | J32: 3790000 | K32: =J32/I32 -> 36796.116 | L32: 6 | M32: Enf Comercializadora | N32: 5664068640 | O32: https://www.inmuebles24.com/propiedades/clasificado/veclcapa-espectacular-casa-col-monumental-147753528.html?n_src=Listado&n_exp=trigger_pills-original&n_pg=1&n_pos=1
B33: =+B32 -> VENTA | C33: =+C32 -> Casa Habitación | E33: Alcalde Barranquitas | F33: Avenida de los Maestros 576 | G33: 4 recámaras, 2 baños uso de suelo mixto, comercial y habitacional, cuarto de servicio con baño, área de lavandería | H33: 314 | I33: 201 | J33: 7500000 | K33: =J33/I33 -> 37313.433 | L33: 40 | M33: iad Inmobiliaria | N33: 5513289530 | O33: https://www.inmuebles24.com/propiedades/clasificado/veclcain-casa-en-venta-en-alcalde-barranquitas-143208861.html?n_src=Listado&n_exp=trigger_pills-original&n_pg=1&n_pos=1
B34: =+B33 -> VENTA | C34: =+C33 -> Casa Habitación | E34: Independencia Oriente | F34: Los Alpes 1548 | G34: Sala y comedor Cocina integral 5 recámaras, 2 baños completos, Jardín lateral, espacio para 1 auto | H34: 175 | I34: 158 | J34: 4200000 | K34: =J34/I34 -> 26582.278 | L34: 40 | M34: Casa Administraciones | N34: 33 3040 8700 | O34: https://www.inmuebles24.com/propiedades/clasificado/veclcain-casa-en-venta-de-un-nivel-en-la-colonia-independencia-147097244.html?n_src=Listado&n_exp=trigger_pills-original&n_pg=1&n_pos=1
B35: =+B34 -> VENTA | C35: =+C34 -> Casa Habitación | K35: =+AVERAGE(K30,K31,K32,K33,K34) -> 34583.378
A37: OTROS COMPARABLES DE VENTA
H38: 200 | I38: 198 | J38: 4100000 | K38: =J38/I38 -> 20707.071 | L38: 40 | O38: https://www.inmuebles24.com/propiedades/clasificado/veclcain-casa-en-belisario-dominguez-gdl-148141350.html?n_src=Listado&n_exp=trigger_pills-original&n_pg=1&n_pos=1
H39: 120 | I39: 140 | J39: 3250000 | K39: =J39/I39 -> 23214.286 | L39: 30 | O39: https://www.inmuebles24.com/propiedades/clasificado/veclcain-casa-con-departamento-independiente-cerca-del-148214120.html?n_src=Listado&n_exp=trigger_pills-original&n_pg=1&n_pos=1
K41: =J41/I41 -> #DIV/0!
K42: =J42/I42 -> #DIV/0!
A45: ESTUDIO MERCADO RENTAS CONSTRUCCIONES | H45: COMPARABLES DE RENTA
A46: FECHA | B46: ESTATUS COMERCIAL: | C46: TIPO: | D46: CIUDAD | E46: COLONIA | F46: DIRECCIÓN: | G46: COMENT: | H46: COMENT: | I46: TERRENO | J46: CONST | K46: RENTA | L46: $ X M2 RENTA | M46: PRECIO HOMOLOGADO SUJETO: | N46: $/m2 VALOR DE VENTA | O46: EDAD: | P46: FUENTE: | Q46: TELÉFONO: | R46: LINK:
B47: RENTA | C47: =+C30 -> Casa Habitación | L47: =+K47/J47 -> #DIV/0! | M47: =+L47*'OPI Constr'!$K$123 -> #DIV/0! | N47: =+(L47*12-(L47*12*0.2839))/0.0661 -> #DIV/0!
B48: =+B47 -> RENTA | C48: =+C47 -> Casa Habitación | L48: =+K48/J48 -> #DIV/0! | M48: =+L48*'OPI Constr'!$K$123 -> #DIV/0! | N48: =+(L48*12-(L48*12*0.2839))/0.0661 -> #DIV/0!
B49: =+B48 -> RENTA | C49: =+C48 -> Casa Habitación | L49: =+K49/J49 -> #DIV/0! | M49: =+L49*'OPI Constr'!$K$123 -> #DIV/0! | N49: =+(L49*12-(L49*12*0.2839))/0.0661 -> #DIV/0!
...

Sheet Ross Heideke
A1: Vida útil: | B1: 70
A2: PARA USAR ESTA TABLA SOLO TECLEA EL NUMERO DE AÑOS DE LA FINCA EN EL CUADRO ROJO Y LE DARA LOS VALORES
A3: 1 | B3: 2 | C3: 3 | D3: 4 | E3: 5 | F3: 6 | G3: 7 | H3: 8 | I3: 9 | J3: 10
A4: ESTADO DE CONSERVACIÓN
A5: EDAD DEL INMUEBLE | B5: Nuevo | C5: Muy Bueno | D5: Bueno | E5: Regular | F5: Remodelado - | G5: Remodelado + | H5: Rehabilitación completa | I5: Ruinoso | J5: Ruinoso Inutilizable | L5: Nuevo
A6: 0 | B6: 1 | C6: =1-0.00032 -> 0.99968 | D6: =1-0.0252 -> 0.9748 | E6: =1-0.0809 -> 0.9191 | F6: =1-0.181 -> 0.819 | G6: =1-0.332 -> 0.668 | H6: =1-0.526 -> 0.474 | I6: =1-0.752 -> 0.248 | J6: 0.1 | L6: Muy Bueno
A7: 1 | B7: =(1-(0.5*(($A7/$B$1)+(($A7/$B$1)^2))))*$B$6 -> 0.9927551 | C7: =(1-(0.5*(($A7/$B$1)+(($A7/$B$1)^2))))*$C$6 -> 0.99243742 | D7: =(1-(0.5*(($A7/$B$1)+(($A7/$B$1)^2))))*$D$6 -> 0.96773767 | E7: =(1-(0.5*(($A7/$B$1)+(($A7/$B$1)^2))))*$E$6 -> 0.91244121 | F7: =(1-(0.5*(($A7/$B$1)+(($A7/$B$1)^2))))*$F$6 -> 0.81306643 | G7: =(1-(0.5*(($A7/$B$1)+(($A7/$B$1)^2))))*$G$6 -> 0.66316041 | H7: =(1-(0.5*(($A7/$B$1)+(($A7/$B$1)^2))))*$H$6 -> 0.47056592 | I7: =(1-(0.5*(($A7/$B$1)+(($A7/$B$1)^2))))*$I$6 -> 0.24620327 | J7: =(1-(0.5*(($A7/$B$1)+(($A7/$B$1)^2))))*$J$6 -> 0.09927551 | L7: Bueno
A8: 2 | B8: =(1-(0.5*(($A8/$B$1)+(($A8/$B$1)^2))))*$B$6 -> 0.98530612 | C8: =(1-(0.5*(($A8/$B$1)+(($A8/$B$1)^2))))*$C$6 -> 0.98499082 | D8: =(1-(0.5*(($A8/$B$1)+(($A8/$B$1)^2))))*$D$6 -> 0.96047641 | E8: =(1-(0.5*(($A8/$B$1)+(($A8/$B$1)^2))))*$E$6 -> 0.90559486 | F8: =(1-(0.5*(($A8/$B$1)+(($A8/$B$1)^2))))*$F$6 -> 0.80696571 | G8: =(1-(0.5*(($A8/$B$1)+(($A8/$B$1)^2))))*$G$6 -> 0.65818449 | H8: =(1-(0.5*(($A8/$B$1)+(($A8/$B$1)^2))))*$H$6 -> 0.4670351 | I8: =(1-(0.5*(($A8/$B$1)+(($A8/$B$1)^2))))*$I$6 -> 0.24435592 | J8: =(1-(0.5*(($A8/$B$1)+(($A8/$B$1)^2))))*$J$6 -> 0.098530612 | L8: Regular
A9: 3 | B9: =(1-(0.5*(($A9/$B$1)+(($A9/$B$1)^2))))*$B$6 -> 0.97765306 | C9: =(1-(0.5*(($A9/$B$1)+(($A9/$B$1)^2))))*$C$6 -> 0.97734021 | D9: =(1-(0.5*(($A9/$B$1)+(($A9/$B$1)^2))))*$D$6 -> 0.9530162 | E9: =(1-(0.5*(($A9/$B$1)+(($A9/$B$1)^2))))*$E$6 -> 0.89856093 | F9: =(1-(0.5*(($A9/$B$1)+(($A9/$B$1)^2))))*$F$6 -> 0.80069786 | G9: =(1-(0.5*(($A9/$B$1)+(($A9/$B$1)^2))))*$G$6 -> 0.65307224 | H9: =(1-(0.5*(($A9/$B$1)+(($A9/$B$1)^2))))*$H$6 -> 0.46340755 | I9: =(1-(0.5*(($A9/$B$1)+(($A9/$B$1)^2))))*$I$6 -> 0.24245796 | J9: =(1-(0.5*(($A9/$B$1)+(($A9/$B$1)^2))))*$J$6 -> 0.097765306 | L9: Remodelado -
A10: 4 | B10: =(1-(0.5*(($A10/$B$1)+(($A10/$B$1)^2))))*$B$6 -> 0.96979592 | C10: =(1-(0.5*(($A10/$B$1)+(($A10/$B$1)^2))))*$C$6 -> 0.96948558 | D10: =(1-(0.5*(($A10/$B$1)+(($A10/$B$1)^2))))*$D$6 -> 0.94535706 | E10: =(1-(0.5*(($A10/$B$1)+(($A10/$B$1)^2))))*$E$6 -> 0.89133943 | F10: =(1-(0.5*(($A10/$B$1)+(($A10/$B$1)^2))))*$F$6 -> 0.79426286 | G10: =(1-(0.5*(($A10/$B$1)+(($A10/$B$1)^2))))*$G$6 -> 0.64782367 | H10: =(1-(0.5*(($A10/$B$1)+(($A10/$B$1)^2))))*$H$6 -> 0.45968327 | I10: =(1-(0.5*(($A10/$B$1)+(($A10/$B$1)^2))))*$I$6 -> 0.24050939 | J10: =(1-(0.5*(($A10/$B$1)+(($A10/$B$1)^2))))*$J$6 -> 0.096979592 | L10: Remodelado +
A11: 5 | B11: =(1-(0.5*(($A11/$B$1)+(($A11/$B$1)^2))))*$B$6 -> 0.96173469 | C11: =(1-(0.5*(($A11/$B$1)+(($A11/$B$1)^2))))*$C$6 -> 0.96142694 | D11: =(1-(0.5*(($A11/$B$1)+(($A11/$B$1)^2))))*$D$6 -> 0.93749898 | E11: =(1-(0.5*(($A11/$B$1)+(($A11/$B$1)^2))))*$E$6 -> 0.88393036 | F11: =(1-(0.5*(($A11/$B$1)+(($A11/$B$1)^2))))*$F$6 -> 0.78766071 | G11: =(1-(0.5*(($A11/$B$1)+(($A11/$B$1)^2))))*$G$6 -> 0.64243878 | H11: =(1-(0.5*(($A11/$B$1)+(($A11/$B$1)^2))))*$H$6 -> 0.45586224 | I11: =(1-(0.5*(($A11/$B$1)+(($A11/$B$1)^2))))*$I$6 -> 0.2385102 | J11: =(1-(0.5*(($A11/$B$1)+(($A11/$B$1)^2))))*$J$6 -> 0.096173469 | L11: Rehabilitación completa
A12: 6 | B12: =(1-(0.5*(($A12/$B$1)+(($A12/$B$1)^2))))*$B$6 -> 0.95346939 | C12: =(1-(0.5*(($A12/$B$1)+(($A12/$B$1)^2))))*$C$6 -> 0.95316428 | D12: =(1-(0.5*(($A12/$B$1)+(($A12/$B$1)^2))))*$D$6 -> 0.92944196 | E12: =(1-(0.5*(($A12/$B$1)+(($A12/$B$1)^2))))*$E$6 -> 0.87633371 | F12: =(1-(0.5*(($A12/$B$1)+(($A12/$B$1)^2))))*$F$6 -> 0.78089143 | G12: =(1-(0.5*(($A12/$B$1)+(($A12/$B$1)^2))))*$G$6 -> 0.63691755 | H12: =(1-(0.5*(($A12/$B$1)+(($A12/$B$1)^2))))*$H$6 -> 0.45194449 | I12: =(1-(0.5*(($A12/$B$1)+(($A12/$B$1)^2))))*$I$6 -> 0.23646041 | J12: =(1-(0.5*(($A12/$B$1)+(($A12/$B$1)^2))))*$J$6 -> 0.095346939 | L12: Ruinoso
A13: 7 | B13: =(1-(0.5*(($A13/$B$1)+(($A13/$B$1)^2))))*$B$6 -> 0.945 | C13: =(1-(0.5*(($A13/$B$1)+(($A13/$B$1)^2))))*$C$6 -> 0.9446976 | D13: =(1-(0.5*(($A13/$B$1)+(($A13/$B$1)^2))))*$D$6 -> 0.921186 | E13: =(1-(0.5*(($A13/$B$1)+(($A13/$B$1)^2))))*$E$6 -> 0.8685495 | F13: =(1-(0.5*(($A13/$B$1)+(($A13/$B$1)^2))))*$F$6 -> 0.773955 | G13: =(1-(0.5*(($A13/$B$1)+(($A13/$B$1)^2))))*$G$6 -> 0.63126 | H13: =(1-(0.5*(($A13/$B$1)+(($A13/$B$1)^2))))*$H$6 -> 0.44793 | I13: =(1-(0.5*(($A13/$B$1)+(($A13/$B$1)^2))))*$I$6 -> 0.23436 | J13: =(1-(0.5*(($A13/$B$1)+(($A13/$B$1)^2))))*$J$6 -> 0.0945 | L13: Ruinoso Inutilizable
A14: 8 | B14: =(1-(0.5*(($A14/$B$1)+(($A14/$B$1)^2))))*$B$6 -> 0.93632653 | C14: =(1-(0.5*(($A14/$B$1)+(($A14/$B$1)^2))))*$C$6 -> 0.93602691 | D14: =(1-(0.5*(($A14/$B$1)+(($A14/$B$1)^2))))*$D$6 -> 0.9127311 | E14: =(1-(0.5*(($A14/$B$1)+(($A14/$B$1)^2))))*$E$6 -> 0.86057771 | F14: =(1-(0.5*(($A14/$B$1)+(($A14/$B$1)^2))))*$F$6 -> 0.76685143 | G14: =(1-(0.5*(($A14/$B$1)+(($A14/$B$1)^2))))*$G$6 -> 0.62546612 | H14: =(1-(0.5*(($A14/$B$1)+(($A14/$B$1)^2))))*$H$6 -> 0.44381878 | I14: =(1-(0.5*(($A14/$B$1)+(($A14/$B$1)^2))))*$I$6 -> 0.23220898 | J14: =(1-(0.5*(($A14/$B$1)+(($A14/$B$1)^2))))*$J$6 -> 0.093632653
A15: 9 | B15: =(1-(0.5*(($A15/$B$1)+(($A15/$B$1)^2))))*$B$6 -> 0.92744898 | C15: =(1-(0.5*(($A15/$B$1)+(($A15/$B$1)^2))))*$C$6 -> 0.9271522 | D15: =(1-(0.5*(($A15/$B$1)+(($A15/$B$1)^2))))*$D$6 -> 0.90407727 | E15: =(1-(0.5*(($A15/$B$1)+(($A15/$B$1)^2))))*$E$6 -> 0.85241836 | F15: =(1-(0.5*(($A15/$B$1)+(($A15/$B$1)^2))))*$F$6 -> 0.75958071 | G15: =(1-(0.5*(($A15/$B$1)+(($A15/$B$1)^2))))*$G$6 -> 0.61953592 | H15: =(1-(0.5*(($A15/$B$1)+(($A15/$B$1)^2))))*$H$6 -> 0.43961082 | I15: =(1-(0.5*(($A15/$B$1)+(($A15/$B$1)^2))))*$I$6 -> 0.23000735 | J15: =(1-(0.5*(($A15/$B$1)+(($A15/$B$1)^2))))*$J$6 -> 0.092744898
A16: 10 | B16: =(1-(0.5*(($A16/$B$1)+(($A16/$B$1)^2))))*$B$6 -> 0.91836735 | C16: =(1-(0.5*(($A16/$B$1)+(($A16/$B$1)^2))))*$C$6 -> 0.91807347 | D16: =(1-(0.5*(($A16/$B$1)+(($A16/$B$1)^2))))*$D$6 -> 0.89522449 | E16: =(1-(0.5*(($A16/$B$1)+(($A16/$B$1)^2))))*$E$6 -> 0.84407143 | F16: =(1-(0.5*(($A16/$B$1)+(($A16/$B$1)^2))))*$F$6 -> 0.75214286 | G16: =(1-(0.5*(($A16/$B$1)+(($A16/$B$1)^2))))*$G$6 -> 0.61346939 | H16: =(1-(0.5*(($A16/$B$1)+(($A16/$B$1)^2))))*$H$6 -> 0.43530612 | I16: =(1-(0.5*(($A16/$B$1)+(($A16/$B$1)^2))))*$I$6 -> 0.2277551 | J16: =(1-(0.5*(($A16/$B$1)+(($A16/$B$1)^2))))*$J$6 -> 0.091836735
A17: 11 | B17: =(1-(0.5*(($A17/$B$1)+(($A17/$B$1)^2))))*$B$6 -> 0.90908163 | C17: =(1-(0.5*(($A17/$B$1)+(($A17/$B$1)^2))))*$C$6 -> 0.90879073 | D17: =(1-(0.5*(($A17/$B$1)+(($A17/$B$1)^2))))*$D$6 -> 0.88617278 | E17: =(1-(0.5*(($A17/$B$1)+(($A17/$B$1)^2))))*$E$6 -> 0.83553693 | F17: =(1-(0.5*(($A17/$B$1)+(($A17/$B$1)^2))))*$F$6 -> 0.74453786 | G17: =(1-(0.5*(($A17/$B$1)+(($A17/$B$1)^2))))*$G$6 -> 0.60726653 | H17: =(1-(0.5*(($A17/$B$1)+(($A17/$B$1)^2))))*$H$6 -> 0.43090469 | I17: =(1-(0.5*(($A17/$B$1)+(($A17/$B$1)^2))))*$I$6 -> 0.22545224 | J17: =(1-(0.5*(($A17/$B$1)+(($A17/$B$1)^2))))*$J$6 -> 0.090908163
A18: 12 | B18: =(1-(0.5*(($A18/$B$1)+(($A18/$B$1)^2))))*$B$6 -> 0.89959184 | C18: =(1-(0.5*(($A18/$B$1)+(($A18/$B$1)^2))))*$C$6 -> 0.89930397 | D18: =(1-(0.5*(($A18/$B$1)+(($A18/$B$1)^2))))*$D$6 -> 0.87692212 | E18: =(1-(0.5*(($A18/$B$1)+(($A18/$B$1)^2))))*$E$6 -> 0.82681486 | F18: =(1-(0.5*(($A18/$B$1)+(($A18/$B$1)^2))))*$F$6 -> 0.73676571 | G18: =(1-(0.5*(($A18/$B$1)+(($A18/$B$1)^2))))*$G$6 -> 0.60092735 | H18: =(1-(0.5*(($A18/$B$1)+(($A18/$B$1)^2))))*$H$6 -> 0.42640653 | I18: =(1-(0.5*(($A18/$B$1)+(($A18/$B$1)^2))))*$I$6 -> 0.22309878 | J18: =(1-(0.5*(($A18/$B$1)+(($A18/$B$1)^2))))*$J$6 -> 0.089959184
A19: 13 | B19: =(1-(0.5*(($A19/$B$1)+(($A19/$B$1)^2))))*$B$6 -> 0.88989796 | C19: =(1-(0.5*(($A19/$B$1)+(($A19/$B$1)^2))))*$C$6 -> 0.88961319 | D19: =(1-(0.5*(($A19/$B$1)+(($A19/$B$1)^2))))*$D$6 -> 0.86747253 | E19: =(1-(0.5*(($A19/$B$1)+(($A19/$B$1)^2))))*$E$6 -> 0.81790521 | F19: =(1-(0.5*(($A19/$B$1)+(($A19/$B$1)^2))))*$F$6 -> 0.72882643 | G19: =(1-(0.5*(($A19/$B$1)+(($A19/$B$1)^2))))*$G$6 -> 0.59445184 | H19: =(1-(0.5*(($A19/$B$1)+(($A19/$B$1)^2))))*$H$6 -> 0.42181163 | I19: =(1-(0.5*(($A19/$B$1)+(($A19/$B$1)^2))))*$I$6 -> 0.22069469 | J19: =(1-(0.5*(($A19/$B$1)+(($A19/$B$1)^2))))*$J$6 -> 0.088989796
A20: 14 | B20: =(1-(0.5*(($A20/$B$1)+(($A20/$B$1)^2))))*$B$6 -> 0.88 | C20: =(1-(0.5*(($A20/$B$1)+(($A20/$B$1)^2))))*$C$6 -> 0.8797184 | D20: =(1-(0.5*(($A20/$B$1)+(($A20/$B$1)^2))))*$D$6 -> 0.857824 | E20: =(1-(0.5*(($A20/$B$1)+(($A20/$B$1)^2))))*$E$6 -> 0.808808 | F20: =(1-(0.5*(($A20/$B$1)+(($A20/$B$1)^2))))*$F$6 -> 0.72072 | G20: =(1-(0.5*(($A20/$B$1)+(($A20/$B$1)^2))))*$G$6 -> 0.58784 | H20: =(1-(0.5*(($A20/$B$1)+(($A20/$B$1)^2))))*$H$6 -> 0.41712 | I20: =(1-(0.5*(($A20/$B$1)+(($A20/$B$1)^2))))*$I$6 -> 0.21824 | J20: =(1-(0.5*(($A20/$B$1)+(($A20/$B$1)^2))))*$J$6 -> 0.088
